<?xml version="1.0" ?>
<!-- =================================================================================== -->
<!-- |    This document was autogenerated by xacro from robot.xacro                    | -->
<!-- |    EDITING THIS FILE BY HAND IS NOT RECOMMENDED                                 | -->
<!-- =================================================================================== -->
<robot name="acs_robot">
  <!-- =============== Link & Joint =============== -->
  <!-- Base -->
  <link name="base_footprint"/>
  <joint name="base_link_joint" type="fixed">
    <origin rpy="0 0 0" xyz="0 0 0"/>
    <parent link="base_footprint"/>
    <child link="base_link"/>
  </joint>
  <link name="base_link">
    <visual>
      <geometry>
        <mesh filename="package://robot_description/meshes/DAE/base/base_link.dae"/>
      </geometry>
    </visual>
    <collision>
      <geometry>
        <mesh filename="package://robot_description/meshes/STL/base/base_link.stl"/>
      </geometry>
    </collision>
    <inertial>
      <origin xyz="0.11 0 0.09"/>
      <mass value="9.7"/>
      <inertia ixx="0.075" ixy="-0.0017" ixz="-0.0017" iyy="0.4" iyz="-0.0008" izz="0.43"/>
    </inertial>
    <surface>
      <friction>
        <ode>
          <mu>0.8</mu>
          <mu2>0.8</mu2>
          <kp>1e15</kp>
          <kd>1e13</kd>
        </ode>
      </friction>
      <bounce>
        <restitution_coefficient>0.01</restitution_coefficient>
        <threshold>10</threshold>
      </bounce>
      <contact>
        <ode>
          <max_vel>0.01</max_vel>
          <minDepth>0</minDepth>
          <contact_surface_layer>0</contact_surface_layer>
        </ode>
      </contact>
    </surface>
  </link>
  <joint name="rear_left_leg_joint" type="revolute">
    <origin rpy="0 1.57079637 -1.57079637" xyz="-0.277 0.06 0.089405"/>
    <parent link="base_link"/>
    <child link="rear_left_leg_joint_link"/>
    <limit effort="500" lower="-3.14159" upper="3.14159" velocity="10"/>
    <dynamics damping="0.005" friction="0.1"/>
    <axis xyz="0 -1 0"/>
  </joint>
  <link name="rear_left_leg_joint_link">
    <visual>
      <geometry>
        <mesh filename="package://robot_description/meshes/DAE/leg_joint/leg_joint.dae"/>
      </geometry>
    </visual>
    <collision>
      <geometry>
        <mesh filename="package://robot_description/meshes/STL/leg_joint/leg_joint.stl"/>
      </geometry>
    </collision>
    <inertial>
      <origin xyz="0 0 -0.038"/>
      <mass value="1.16"/>
      <inertia ixx="0.002" ixy="0.0" ixz="0.0" iyy="0.002" iyz="0.0" izz="0.001"/>
    </inertial>
  </link>
  <joint name="rear_right_leg_joint" type="revolute">
    <origin rpy="0 -1.57079637 -1.57079637" xyz="-0.277 -0.06 0.089405"/>
    <parent link="base_link"/>
    <child link="rear_right_leg_joint_link"/>
    <limit effort="500" lower="-3.14159" upper="3.14159" velocity="10"/>
    <dynamics damping="0.005" friction="0.1"/>
    <axis xyz="0 1 0"/>
  </joint>
  <link name="rear_right_leg_joint_link">
    <visual>
      <geometry>
        <mesh filename="package://robot_description/meshes/DAE/leg_joint/leg_joint.dae"/>
      </geometry>
    </visual>
    <collision>
      <geometry>
        <mesh filename="package://robot_description/meshes/STL/leg_joint/leg_joint.stl"/>
      </geometry>
    </collision>
    <inertial>
      <origin xyz="0 0 -0.038"/>
      <mass value="1.16"/>
      <inertia ixx="0.002" ixy="0.0" ixz="0.0" iyy="0.002" iyz="0.0" izz="0.001"/>
    </inertial>
  </link>
  <joint name="front_left_leg_joint" type="revolute">
    <origin rpy="0 1.57079637 -1.57079637" xyz="0.282 0.06 0.090255"/>
    <parent link="base_link"/>
    <child link="front_left_leg_joint_link"/>
    <limit effort="500" lower="-3.14159" upper="3.14159" velocity="10"/>
    <dynamics damping="0.005" friction="0.1"/>
    <axis xyz="0 -1 0"/>
  </joint>
  <link name="front_left_leg_joint_link">
    <visual>
      <geometry>
        <mesh filename="package://robot_description/meshes/DAE/leg_joint/leg_joint.dae"/>
      </geometry>
    </visual>
    <collision>
      <geometry>
        <mesh filename="package://robot_description/meshes/STL/leg_joint/leg_joint.stl"/>
      </geometry>
    </collision>
    <inertial>
      <origin xyz="0 0 -0.038"/>
      <mass value="1.16"/>
      <inertia ixx="0.002" ixy="0.0" ixz="0.0" iyy="0.002" iyz="0.0" izz="0.001"/>
    </inertial>
  </link>
  <joint name="front_right_leg_joint" type="revolute">
    <origin rpy="0 -1.57079637 -1.57079637" xyz="0.282 -0.06 0.090255"/>
    <parent link="base_link"/>
    <child link="front_right_leg_joint_link"/>
    <limit effort="500" lower="-3.14159" upper="3.14159" velocity="10"/>
    <dynamics damping="0.005" friction="0.1"/>
    <axis xyz="0 1 0"/>
  </joint>
  <link name="front_right_leg_joint_link">
    <visual>
      <geometry>
        <mesh filename="package://robot_description/meshes/DAE/leg_joint/leg_joint.dae"/>
      </geometry>
    </visual>
    <collision>
      <geometry>
        <mesh filename="package://robot_description/meshes/STL/leg_joint/leg_joint.stl"/>
      </geometry>
    </collision>
    <inertial>
      <origin xyz="0 0 -0.038"/>
      <mass value="1.16"/>
      <inertia ixx="0.002" ixy="0.0" ixz="0.0" iyy="0.002" iyz="0.0" izz="0.001"/>
    </inertial>
  </link>
  <joint name="front_left_thigh_joint" type="revolute">
    <origin rpy="1.57079637 0 -1.57079637" xyz="0 0 -0.114"/>
    <parent link="front_left_leg_joint_link"/>
    <child link="front_left_thigh_link"/>
    <limit effort="500" lower="-3" upper="3" velocity="10"/>
    <dynamics damping="0.005" friction="0.1"/>
    <axis xyz="0 1 0"/>
  </joint>
  <link name="front_left_thigh_link">
    <visual>
      <geometry>
        <mesh filename="package://robot_description/meshes/DAE/left_thigh/left_thigh.dae"/>
      </geometry>
    </visual>
    <collision>
      <geometry>
        <mesh filename="package://robot_description/meshes/STL/left_thigh/left_thigh.stl"/>
      </geometry>
    </collision>
    <inertial>
      <origin xyz="0.17 -0.028 0.014"/>
      <mass value="1.24"/>
      <inertia ixx="0.002" ixy="0" ixz="0" iyy="0.002" iyz="0" izz="0.001"/>
      <!-- inertia ixx="-0.5" ixy="0.003" ixz="0.145" iyy="-0.496" iyz="-0.0096" izz="0.012" -->
    </inertial>
  </link>
  <joint name="rear_left_thigh_joint" type="revolute">
    <origin rpy="1.57079637 0 -1.57079637" xyz="0 0 -0.114"/>
    <parent link="rear_left_leg_joint_link"/>
    <child link="rear_left_thigh_link"/>
    <limit effort="500" lower="-3" upper="3" velocity="10"/>
    <dynamics damping="0.005" friction="0.1"/>
    <axis xyz="0 1 0"/>
  </joint>
  <link name="rear_left_thigh_link">
    <visual>
      <geometry>
        <mesh filename="package://robot_description/meshes/DAE/left_thigh/left_thigh.dae"/>
      </geometry>
    </visual>
    <collision>
      <geometry>
        <mesh filename="package://robot_description/meshes/STL/left_thigh/left_thigh.stl"/>
      </geometry>
    </collision>
    <inertial>
      <origin xyz="0.17 -0.028 0.014"/>
      <mass value="1.24"/>
      <inertia ixx="0.002" ixy="0" ixz="0" iyy="0.002" iyz="0" izz="0.001"/>
      <!-- inertia ixx="-0.5" ixy="0.003" ixz="0.145" iyy="-0.496" iyz="-0.0096" izz="0.012" -->
    </inertial>
  </link>
  <joint name="front_right_thigh_joint" type="revolute">
    <origin rpy="1.57079637 0 -1.57079637" xyz="0 0 -0.114"/>
    <parent link="front_right_leg_joint_link"/>
    <child link="front_right_thigh_link"/>
    <limit effort="500" lower="-3" upper="3" velocity="10"/>
    <dynamics damping="0.005" friction="0.1"/>
    <axis xyz="0 -1 0"/>
  </joint>
  <link name="front_right_thigh_link">
    <visual>
      <geometry>
        <mesh filename="package://robot_description/meshes/DAE/right_thigh/right_thigh.dae"/>
      </geometry>
    </visual>
    <collision>
      <geometry>
        <mesh filename="package://robot_description/meshes/STL/right_thigh/right_thigh.stl"/>
      </geometry>
    </collision>
    <inertial>
      <origin xyz="0.17 -0.028 -0.014"/>
      <mass value="1.24"/>
      <inertia ixx="0.002" ixy="0.0" ixz="0.0" iyy="0.002" iyz="0.0" izz="0.001"/>
      <!--inertia ixx="-0.44" ixy="0.012" ixz="0.14" iyy="-0.423" iyz="0.0217" izz="0.0135" -->
    </inertial>
  </link>
  <joint name="rear_right_thigh_joint" type="revolute">
    <origin rpy="1.57079637 0 -1.57079637" xyz="0 0 -0.114"/>
    <parent link="rear_right_leg_joint_link"/>
    <child link="rear_right_thigh_link"/>
    <limit effort="500" lower="-3" upper="3" velocity="10"/>
    <dynamics damping="0.005" friction="0.1"/>
    <axis xyz="0 -1 0"/>
  </joint>
  <link name="rear_right_thigh_link">
    <visual>
      <geometry>
        <mesh filename="package://robot_description/meshes/DAE/right_thigh/right_thigh.dae"/>
      </geometry>
    </visual>
    <collision>
      <geometry>
        <mesh filename="package://robot_description/meshes/STL/right_thigh/right_thigh.stl"/>
      </geometry>
    </collision>
    <inertial>
      <origin xyz="0.17 -0.028 -0.014"/>
      <mass value="1.24"/>
      <inertia ixx="0.002" ixy="0.0" ixz="0.0" iyy="0.002" iyz="0.0" izz="0.001"/>
      <!--inertia ixx="-0.44" ixy="0.012" ixz="0.14" iyy="-0.423" iyz="0.0217" izz="0.0135" -->
    </inertial>
  </link>
  <joint name="front_left_shin_joint" type="revolute">
    <origin rpy="0 0 0" xyz="0.426 -0.0285 0"/>
    <parent link="front_left_thigh_link"/>
    <child link="front_left_shin_link"/>
    <limit effort="500" lower="-3.14159" upper="3.14159" velocity="10"/>
    <dynamics damping="0.005" friction="0.1"/>
    <axis xyz="0 1 0"/>
  </joint>
  <link name="front_left_shin_link">
    <visual>
      <geometry>
        <mesh filename="package://robot_description/meshes/DAE/shin/shin.dae"/>
      </geometry>
    </visual>
    <collision>
      <geometry>
        <mesh filename="package://robot_description/meshes/STL/shin/shin.stl"/>
      </geometry>
    </collision>
    <inertial>
      <origin xyz="-0.158 0.011 0.0"/>
      <mass value="0.66"/>
      <inertia ixx="0.0003" ixy="0.0013" ixz="0.000045" iyy="0.029" iyz="-0.000003" izz="0.029"/>
    </inertial>
  </link>
  <joint name="front_right_shin_joint" type="revolute">
    <origin rpy="3.14159274 0 0" xyz="0.426 -0.0285 0"/>
    <parent link="front_right_thigh_link"/>
    <child link="front_right_shin_link"/>
    <limit effort="500" lower="-3.14159" upper="3.14159" velocity="10"/>
    <dynamics damping="0.005" friction="0.1"/>
    <axis xyz="0 1 0"/>
  </joint>
  <link name="front_right_shin_link">
    <visual>
      <geometry>
        <mesh filename="package://robot_description/meshes/DAE/shin/shin.dae"/>
      </geometry>
    </visual>
    <collision>
      <geometry>
        <mesh filename="package://robot_description/meshes/STL/shin/shin.stl"/>
      </geometry>
    </collision>
    <inertial>
      <origin xyz="-0.158 0.011 0.0"/>
      <mass value="0.66"/>
      <inertia ixx="0.0003" ixy="0.0013" ixz="0.000045" iyy="0.029" iyz="-0.000003" izz="0.029"/>
    </inertial>
  </link>
  <joint name="rear_left_shin_joint" type="revolute">
    <origin rpy="0 0 0" xyz="0.426 -0.0285 0"/>
    <parent link="rear_left_thigh_link"/>
    <child link="rear_left_shin_link"/>
    <limit effort="500" lower="-3.14159" upper="3.14159" velocity="10"/>
    <dynamics damping="0.005" friction="0.1"/>
    <axis xyz="0 1 0"/>
  </joint>
  <link name="rear_left_shin_link">
    <visual>
      <geometry>
        <mesh filename="package://robot_description/meshes/DAE/shin/shin.dae"/>
      </geometry>
    </visual>
    <collision>
      <geometry>
        <mesh filename="package://robot_description/meshes/STL/shin/shin.stl"/>
      </geometry>
    </collision>
    <inertial>
      <origin xyz="-0.158 0.011 0.0"/>
      <mass value="0.66"/>
      <inertia ixx="0.0003" ixy="0.0013" ixz="0.000045" iyy="0.029" iyz="-0.000003" izz="0.029"/>
    </inertial>
  </link>
  <joint name="rear_right_shin_joint" type="revolute">
    <origin rpy="3.14159274 0 0" xyz="0.426 -0.0285 0"/>
    <parent link="rear_right_thigh_link"/>
    <child link="rear_right_shin_link"/>
    <limit effort="500" lower="-3.14159" upper="3.14159" velocity="10"/>
    <dynamics damping="0.005" friction="0.1"/>
    <axis xyz="0 1 0"/>
  </joint>
  <link name="rear_right_shin_link">
    <visual>
      <geometry>
        <mesh filename="package://robot_description/meshes/DAE/shin/shin.dae"/>
      </geometry>
    </visual>
    <collision>
      <geometry>
        <mesh filename="package://robot_description/meshes/STL/shin/shin.stl"/>
      </geometry>
    </collision>
    <inertial>
      <origin xyz="-0.158 0.011 0.0"/>
      <mass value="0.66"/>
      <inertia ixx="0.0003" ixy="0.0013" ixz="0.000045" iyy="0.029" iyz="-0.000003" izz="0.029"/>
    </inertial>
  </link>
  <ros2_control name="fws" type="system">
    <hardware>
      <plugin>gz_ros2_control/GazeboSimSystem</plugin>
    </hardware>
    <joint name="front_left_leg_joint">
      <command_interface name="position">
        <param name="min">-3.14</param>
        <param name="max">3.14</param>
      </command_interface>
      <state_interface name="position"/>
    </joint>
    <joint name="front_right_leg_joint">
      <command_interface name="position">
        <param name="min">-3.14</param>
        <param name="max">3.14</param>
      </command_interface>
      <state_interface name="position"/>
    </joint>
    <joint name="rear_left_leg_joint">
      <command_interface name="position">
        <param name="min">-3.14</param>
        <param name="max">3.14</param>
      </command_interface>
      <state_interface name="position"/>
    </joint>
    <joint name="rear_right_leg_joint">
      <command_interface name="position">
        <param name="min">-3.14</param>
        <param name="max">3.14</param>
      </command_interface>
      <state_interface name="position"/>
    </joint>
    <joint name="front_left_thigh_joint">
      <command_interface name="position">
        <param name="min">-3.14</param>
        <param name="max">3.14</param>
      </command_interface>
      <state_interface name="position"/>
    </joint>
    <joint name="front_right_thigh_joint">
      <command_interface name="position">
        <param name="min">-3.14</param>
        <param name="max">3.14</param>
      </command_interface>
      <state_interface name="position"/>
    </joint>
    <joint name="rear_left_thigh_joint">
      <command_interface name="position">
        <param name="min">-3.14</param>
        <param name="max">3.14</param>
      </command_interface>
      <state_interface name="position"/>
    </joint>
    <joint name="rear_right_thigh_joint">
      <command_interface name="position">
        <param name="min">-3.14</param>
        <param name="max">3.14</param>
      </command_interface>
      <state_interface name="position"/>
    </joint>
    <joint name="front_left_shin_joint">
      <command_interface name="position">
        <param name="min">-3.14</param>
        <param name="max">3.14</param>
      </command_interface>
      <state_interface name="position"/>
    </joint>
    <joint name="front_right_shin_joint">
      <command_interface name="position">
        <param name="min">-3.14</param>
        <param name="max">3.14</param>
      </command_interface>
      <state_interface name="position"/>
    </joint>
    <joint name="rear_left_shin_joint">
      <command_interface name="position">
        <param name="min">-3.14</param>
        <param name="max">3.14</param>
      </command_interface>
      <state_interface name="position"/>
    </joint>
    <joint name="rear_right_shin_joint">
      <command_interface name="position">
        <param name="min">-3.14</param>
        <param name="max">3.14</param>
      </command_interface>
      <state_interface name="position"/>
    </joint>
  </ros2_control>
  <gazebo>
    <plugin filename="gz_ros2_control-system" name="gz_ros2_control::GazeboSimROS2ControlPlugin">
      <parameters>/root/sim/ros_ws/install/robot_description/share/robot_description/config/robot_controller.yaml</parameters>
    </plugin>
    <plugin filename="libgz-sim-joint-state-publisher-system" name="gz::sim::systems::JointStatePublisher">
    </plugin>
    <plugin filename="libgz-sim-pose-publisher-system" name="gz::sim::systems::PosePublisher">
      <publish_link_pose>true</publish_link_pose>
      <use_pose_vector_msg>true</use_pose_vector_msg>
      <publish_nested_model_pose>true</publish_nested_model_pose>
    </plugin>
    <plugin filename="ignition-gazebo-sensors-system" name="ignition::gazebo::systems::Sensors">
      <render_engine>ogre2</render_engine>
    </plugin>
    <plugin filename="gz-sim-imu-system" name="gz::sim::systems::Imu">
    </plugin>
  </gazebo>
  <gazebo reference="base_link">
    <selfCollide>false</selfCollide>
    <mu1 value="0.05"/>
    <mu2 value="0.05"/>
    <sensor name="imu_sensor" type="imu">
      <always_on>1</always_on>
      <update_rate>100</update_rate>
      <visualize>true</visualize>
      <topic>imu</topic>
    </sensor>
  </gazebo>
  <gazebo reference="rear_left_leg_joint_link">
    <selfCollide>false</selfCollide>
    <mu1 value="0.2"/>
    <mu2 value="0.2"/>
  </gazebo>
  <gazebo reference="front_left_leg_joint_link">
    <selfCollide>false</selfCollide>
    <mu1 value="0.2"/>
    <mu2 value="0.2"/>
  </gazebo>
  <gazebo reference="rear_right_leg_joint_link">
    <selfCollide>false</selfCollide>
    <mu1 value="0.2"/>
    <mu2 value="0.2"/>
  </gazebo>
  <gazebo reference="front_right_leg_joint_link">
    <selfCollide>false</selfCollide>
    <mu1 value="0.2"/>
    <mu2 value="0.2"/>
  </gazebo>
  <gazebo reference="front_left_thigh_link">
    <selfCollide>false</selfCollide>
    <mu1 value="0.2"/>
    <mu2 value="0.2"/>
  </gazebo>
  <gazebo reference="rear_left_thigh_link">
    <selfCollide>false</selfCollide>
    <mu1 value="0.2"/>
    <mu2 value="0.2"/>
  </gazebo>
  <gazebo reference="front_leg_joint_link">
    <selfCollide>false</selfCollide>
    <mu1 value="0.2"/>
    <mu2 value="0.2"/>
  </gazebo>
  <gazebo reference="rear_leg_joint_link">
    <selfCollide>false</selfCollide>
    <mu1 value="0.2"/>
    <mu2 value="0.2"/>
  </gazebo>
  <gazebo reference="rear_left_shin_link">
    <selfCollide>false</selfCollide>
    <mu1>1.0</mu1>
    <mu2>1.0</mu2>
    <minDepth>0.0002</minDepth>
    <kp value="1000000.0"/>
    <kd value="100.0"/>
  </gazebo>
  <gazebo reference="front_left_shin_link">
    <selfCollide>false</selfCollide>
    <mu1>1.0</mu1>
    <mu2>1.0</mu2>
    <minDepth>0.0002</minDepth>
    <kp value="1000000.0"/>
    <kd value="100.0"/>
  </gazebo>
  <gazebo reference="rear_right_shin_link">
    <selfCollide>false</selfCollide>
    <mu1>1.0</mu1>
    <mu2>1.0</mu2>
    <minDepth>0.0002</minDepth>
    <kp value="1000000.0"/>
    <kd value="100.0"/>
  </gazebo>
  <gazebo reference="front_right_shin_link">
    <selfCollide>false</selfCollide>
    <mu1>1.0</mu1>
    <mu2>1.0</mu2>
    <minDepth>0.0002</minDepth>
    <kp value="1000000.0"/>
    <kd value="100.0"/>
  </gazebo>
</robot>
